<?xml version="1.0"?>
<robot xmlns:xacro="http://www.ros.org/wiki/xacro">

    <!-- Include external files -->
    <xacro:include filename="inertial_macros.xacro" />

    <material name="white">
        <color rgba="1 1 1 1" />
    </material>

    <material name="orange">
        <color rgba="1 0.3 0.1 1" />
    </material>

    <material name="blue">
        <color rgba="0.2 0.2 1 1" />
    </material>

    <material name="black">
        <color rgba="0 0 0 1" />
    </material>

    <!-- Base Link -->
    <link name="base_link">

    </link>

    <!-- Chassis Link -->
    <joint name="chassis_joint" type="fixed">
        <parent link="base_link" />
        <child link="chassis" />
        <origin xyz="-0.15 0 0" />
    </joint>

    <link name="chassis">
        <visual>
            <origin xyz="0.15 0 0.05" />
            <geometry>
                <box size="0.3 0.19 0.1" />
            </geometry>
            <material name="white" />
        </visual>
        <collision>
            <origin xyz="0.15 0 0.05" />
            <geometry>
                <box size="0.3 0.19 0.1" />
            </geometry>
        </collision>
        <xacro:inertial_box mass="0.5" x="0.3" y="0.19" z="0.1">
            <origin xyz="0.15 0 0.05" rpy="0 0 0" />
        </xacro:inertial_box>
    </link>

    <gazebo reference="chassis">
        <material>Gazebo/White</material>
    </gazebo>

    <!-- Actuating Left Wheel Link -->
    <joint name="left_wheel_joint" type="continuous">
        <parent link="base_link" />
        <child link="left_wheel" />
        <origin xyz="0 0.095 0" rpy="-${pi/2} 0 0" />
        <axis xyz="0 0 1" />
    </joint>

    <link name="left_wheel">
        <visual>
            <origin xyz="0 0 0.0125" />
            <geometry>
                <cylinder radius="0.03" length="0.025" />
                <material name="blue" />
            </geometry>
        </visual>
        <collision>
            <origin xyz="0 0 0.0125" />
            <geometry>
                <cylinder radius="0.03" length="0.025" />
            </geometry>
        </collision>
        <xacro:inertial_cylinder mass="0.1" radius="0.03" length="0.025">
            <origin xyz="0 0 0.0125" rpy="0 0 0" />
        </xacro:inertial_cylinder>
    </link>

    <gazebo reference="left_wheel">
        <material>Gazebo/Blue</material>
    </gazebo>

    <!-- Actuating Right Wheel Link -->
    <joint name="right_wheel_joint" type="continuous">
        <parent link="base_link" />
        <child link="right_wheel" />
        <origin xyz="0 -0.095 0" rpy="${pi/2} 0 0" />
        <axis xyz="0 0 -1" />
    </joint>

    <link name="right_wheel">
        <visual>
            <origin xyz="0 0 0.0125" />
            <geometry>
                <cylinder radius="0.03" length="0.025" />
                <material name="blue" />
            </geometry>
        </visual>
        <collision>
            <origin xyz="0 0 0.0125" />
            <geometry>
                <cylinder radius="0.03" length="0.025" />
            </geometry>
        </collision>
        <xacro:inertial_cylinder mass="0.1" radius="0.03" length="0.025">
            <origin xyz="0 0 0.0125" rpy="0 0 0" />
        </xacro:inertial_cylinder>
    </link>

    <gazebo reference="right_wheel">
        <material>Gazebo/Blue</material>
    </gazebo>

    <!-- Front caster wheel -->
    <joint name="front_caster_wheel_joint" type="fixed">
        <parent link="chassis" />
        <child link="front_caster_wheel" />
        <origin xyz="0.25 0 0" />
    </joint>

    <link name="front_caster_wheel">
        <visual>
            <geometry>
                <sphere radius="0.03" />
            </geometry>
            <material name="black" />
        </visual>
        <collision>
            <geometry>
                <sphere radius="0.03" />
            </geometry>
        </collision>
        <xacro:inertial_sphere mass="0.1" radius="0.03">
            <origin xyz="0 0 0" rpy="0 0 0" />
        </xacro:inertial_sphere>
    </link>

    <gazebo reference="front_caster_wheel">
        <material>Gazebo/Black</material>
        <mu1 value="0.001" />
        <mu2 value="0.001" />
    </gazebo>


    <!-- Rear caster wheel -->
    <joint name="rear_caster_wheel_joint" type="fixed">
        <parent link="chassis" />
        <child link="rear_caster_wheel" />
        <origin xyz="0.05 0 0" />
    </joint>

    <link name="rear_caster_wheel">
        <visual>
            <geometry>
                <sphere radius="0.03" />
            </geometry>
            <material name="black" />
        </visual>
        <collision>
            <geometry>
                <sphere radius="0.03" />
            </geometry>
        </collision>
        <xacro:inertial_sphere mass="0.1" radius="0.03">
            <origin xyz="0 0 0" rpy="0 0 0" />
        </xacro:inertial_sphere>
    </link>

    <gazebo reference="rear_caster_wheel">
        <material>Gazebo/Black</material>
        <mu1 value="0.001" />
        <mu2 value="0.001" />
    </gazebo>

</robot>